#VRML_SIM R2023a utf8

EXTERNPROTO "https://raw.githubusercontent.com/cyberbotics/webots/R2023a/projects/objects/backgrounds/protos/TexturedBackground.proto"
EXTERNPROTO "https://raw.githubusercontent.com/cyberbotics/webots/R2023a/projects/objects/backgrounds/protos/TexturedBackgroundLight.proto"
EXTERNPROTO "https://raw.githubusercontent.com/cyberbotics/webots/R2023a/projects/objects/floors/protos/Floor.proto"
EXTERNPROTO "https://raw.githubusercontent.com/cyberbotics/webots/R2023a/projects/appearances/protos/Grass.proto"
EXTERNPROTO "https://raw.githubusercontent.com/cyberbotics/webots/R2023a/projects/humans/skin_animated_humans/protos/CharacterSkin.proto"

WorldInfo {
  info [
    "Skin animation of human models."
    "In this example BVH motions are played on FBX MakeHuman models."
    "Author: Guillaume Michel <guillaume.michel.202@gmail.com>"
  ]
  title "Human Skin Animation"
}
Viewpoint {
  orientation -0.22277820233306625 -0.13810816317565874 0.9650367909201665 4.219871998484505
  position 8.078374959353761 7.654898279706237 8.770959636344442
}
TexturedBackground {
  texture "noon_cloudy_countryside"
}
TexturedBackgroundLight {
  texture "noon_cloudy_countryside"
}
Floor {
  size 50 50
  tileSize 2 2
  appearance Grass {
    type "mossy"
  }
}
DEF ROBERT Robot {
  translation -1.59 -3 0
  children [
    Robot {
      translation -0.06 0 2.12
      children [
        Hinge2Joint {
          jointParameters HingeJointParameters {
            axis 0 1 0
          }
          jointParameters2 JointParameters {
          }
          device [
            RotationalMotor {
              name "pitch_gaze"
            }
          ]
          device2 [
            RotationalMotor {
              name "yaw_gaze"
            }
          ]
          endPoint DEF gaze_tracker Solid {
            translation 5.12 0 -5.36315e-06
            rotation 0 -0.9999999999999999 0 1.5707953071795862
            children [
              Shape {
                appearance Appearance {
                  material Material {
                    transparency 0.7
                  }
                }
                geometry Cone {
                  bottomRadius 5.7
                  height 10
                }
              }
            ]
            boundingObject Shape {
              appearance Appearance {
                material Material {
                  transparency 0.7
                }
              }
              geometry IndexedFaceSet {
                coord Coordinate {
                  point [
                    1 0 -1
                    -1 0 -1
                    -1 0 1
                    1 0 1
                    0 2 0
                  ]
                }
                coordIndex [
                  0, 4, 3, -1, 1, 4, 0, -1, 2, 4
                  1, -1, 3, 4, 2, -1, 0, 3, 2, 1
                ]
              }
            }
          }
        }
      ]
      controller "gaze_controller"
      supervisor TRUE
    }
    CharacterSkin {
      name "Robert"
      model "Robert"
    }
  ]
  name "robert"
  controller "bvh_animation"
  controllerArgs [
    "-d"
    "Robert"
    "-f"
    "../../motions/gazev1.bvh"
  ]
  supervisor TRUE
}
