#VRML_SIM R2023a utf8

EXTERNPROTO "https://raw.githubusercontent.com/cyberbotics/webots/R2023a/projects/objects/backgrounds/protos/TexturedBackground.proto"
EXTERNPROTO "https://raw.githubusercontent.com/cyberbotics/webots/R2023a/projects/objects/backgrounds/protos/TexturedBackgroundLight.proto"
EXTERNPROTO "https://raw.githubusercontent.com/cyberbotics/webots/R2023a/projects/objects/floors/protos/Floor.proto"
EXTERNPROTO "https://raw.githubusercontent.com/cyberbotics/webots/R2023a/projects/appearances/protos/Grass.proto"
EXTERNPROTO "https://raw.githubusercontent.com/cyberbotics/webots/R2023a/projects/humans/skin_animated_humans/protos/CharacterSkin.proto"

WorldInfo {
  info [
    "Skin animation of human models."
    "In this example BVH motions are played on FBX MakeHuman models."
    "Author: Guillaume Michel <guillaume.michel.202@gmail.com>"
  ]
  title "Human Skin Animation"
}
Viewpoint {
  orientation 0.31987462652255844 -0.08674955671803708 -0.9434801204669221 3.6425849874442506
  position -1.0017698794857153 -3.3247185548407145 2.896134079021302
}
TexturedBackground {
  texture "noon_cloudy_countryside"
}
TexturedBackgroundLight {
  texture "noon_cloudy_countryside"
}
Floor {
  size 50 50
  tileSize 2 2
  appearance Grass {
    type "mossy"
  }
}
DEF ROBERT Robot {
  translation -1.59 -3 0
  children [
    Robot {
      translation -0.06 0 2.12
      children [
        Hinge2Joint {
          jointParameters HingeJointParameters {
            axis 0 1 0
          }
          jointParameters2 JointParameters {
          }
          device [
            RotationalMotor {
              name "pitch_gaze"
            }
          ]
          device2 [
            RotationalMotor {
              name "yaw_gaze"
            }
          ]
          endPoint Solid {
            translation -0.14 0 0
            rotation 0 1 0 0
            children [
              Shape {
                appearance Appearance {
                  material Material {
                  }
                }
                geometry Box {
                  size 1 0.01 0.01
                }
              }
            ]
          }
        }
      ]
      controller "gaze_controller"
    }
    CharacterSkin {
      name "Robert"
      model "Robert"
    }
  ]
  name "robert"
  controller "bvh_animation"
  controllerArgs [
    "-d"
    "Robert"
    "-f"
    "../../motions/gazev1.bvh"
  ]
  supervisor TRUE
}
