#VRML_SIM R2023a utf8

EXTERNPROTO "https://raw.githubusercontent.com/cyberbotics/webots/R2023a/projects/objects/backgrounds/protos/TexturedBackground.proto"
EXTERNPROTO "https://raw.githubusercontent.com/cyberbotics/webots/R2023a/projects/objects/backgrounds/protos/TexturedBackgroundLight.proto"
EXTERNPROTO "https://raw.githubusercontent.com/cyberbotics/webots/R2023a/projects/objects/floors/protos/Floor.proto"
EXTERNPROTO "https://raw.githubusercontent.com/cyberbotics/webots/R2023a/projects/appearances/protos/Grass.proto"
EXTERNPROTO "https://raw.githubusercontent.com/cyberbotics/webots/R2023a/projects/humans/skin_animated_humans/protos/CharacterSkin.proto"

WorldInfo {
  info [
    "Skin animation of human models."
    "In this example BVH motions are played on FBX MakeHuman models."
    "Author: Guillaume Michel <guillaume.michel.202@gmail.com>"
  ]
  title "Human Skin Animation"
}
Viewpoint {
  orientation 0.2573840107879406 -0.28521391690535425 -0.9232586271431312 4.735211427192399
  position -0.36614663071587317 -11.975083542738691 5.48518058547956
}
TexturedBackground {
  texture "noon_cloudy_countryside"
}
TexturedBackgroundLight {
  texture "noon_cloudy_countryside"
}
Floor {
  size 50 50
  tileSize 2 2
  appearance Grass {
    type "mossy"
  }
}
DEF ROBERT Robot {
  translation -1.59 -3 0
  children [
    Robot {
      translation -0.06 0 2.12
      children [
        Hinge2Joint {
          jointParameters HingeJointParameters {
            axis 0 1 0
          }
          jointParameters2 JointParameters {
          }
          device [
            RotationalMotor {
              name "pitch_gaze"
            }
          ]
          device2 [
            RotationalMotor {
              name "yaw_gaze"
            }
          ]
          endPoint DEF gaze_tracker Solid {
            translation 5.12 0 -5.36315e-06
            rotation 0 -0.9999999999999999 0 1.5707953071795862
            children [
              Shape {
                appearance Appearance {
                  material Material {
                    transparency 0.7
                  }
                }
                geometry Cone {
                  bottomRadius 5.7
                  height 10
                }
              }
            ]
            boundingObject Shape {
              appearance Appearance {
                material Material {
                  transparency 0.7
                }
              }
            }
          }
        }
      ]
      controller "gaze_controller"
    }
    CharacterSkin {
      name "Robert"
      model "Robert"
    }
  ]
  name "robert"
  controller "bvh_animation"
  controllerArgs [
    "-d"
    "Robert"
    "-f"
    "../../motions/gazev1.bvh"
  ]
  supervisor TRUE
}
